Input_Data/hiphop_data.csv
Artist,Genre,key,mode,valence,tempo,year,speechiness,instrumentalness,time_signature
E-40,Hip Hop,F#,Minor,0.609,91.162,1994.0,0.358,2.29e-05,4.0
Dustin,Hip Hop,E,Major,0.0,0.0,2017.0,0.0,0.0,0.0
M.I.A.,Hip Hop,A,Major,0.428,157.7,2001.0,0.0835,0.0168,4.0
Justin Timberlake,Hip Hop,C#,Major,0.882,103.877,2002.0,0.129,5.67e-05,4.0
Justin Timberlake,Hip Hop,E,Major,0.218,100.956,2006.0,0.0344,0.000131,4.0
Snoop Dogg,Hip Hop,B,Minor,0.581,115.256,2001.0,0.0818,0.0,4.0
Xzibit,Hip Hop,C,Minor,0.718,97.487,2002.0,0.224,0.0,4.0
Justin Timberlake,Hip Hop,A#,Minor,0.9,92.914,2002.0,0.0791,0.162,4.0
Snoop Dogg,Hip Hop,C#,Major,0.6759999999999999,90.0,2001.0,0.411,0.0,4.0
Snoop Dogg,Hip Hop,B,Minor,0.7290000000000001,89.959,2001.0,0.344,0.0,4.0
Slum Village,Hip Hop,C,Major,0.536,93.909,2005.0,0.0751,4.3e-06,4.0
Mac Miller,Hip Hop,G,Major,0.259,80.056,2012.0,0.375,4.94e-05,4.0
Tyga,Hip Hop,G#,Major,0.6940000000000001,146.841,2017.0,0.402,0.0,3.0
Plies,Hip Hop,E,Minor,0.0779,139.986,2019.0,0.0735,0.0,4.0
Common,Hip Hop,A#,Minor,0.764,91.9,1997.0,0.266,0.0,4.0
Slum Village,Hip Hop,C#,Minor,0.7140000000000001,85.95299999999996,2005.0,0.37,0.0,4.0
Wyclef Jean,Hip Hop,G#,Major,0.0,0.0,2002.0,0.0,0.0,0.0
Slum Village,Hip Hop,A,Major,0.7170000000000001,105.527,2005.0,0.301,2.15e-06,4.0
21 Savage,Hip Hop,C#,Major,0.306,84.022,2018.0,0.359,1.16e-06,4.0
Lecrae,Hip Hop,G#,Minor,0.228,105.136,2020.0,0.305,0.0,3.0
Soulja Boy,Hip Hop,B,Major,0.16399999999999998,132.984,2018.0,0.363,0.0,4.0
Meek Mill,Hip Hop,E,Minor,0.453,79.012,2018.0,0.331,0.0,4.0
Mystikal,Hip Hop,A,Minor,0.8009999999999999,90.877,1997.0,0.335,0.0,4.0
Chris Brown,Hip Hop,F,Major,0.524,96.488,2014.0,0.0335,0.0,4.0
Gucci Mane,Hip Hop,E,Major,0.6509999999999999,138.013,2020.0,0.0671,0.000285,4.0
Kris Kross,Hip Hop,B,Minor,0.529,98.082,1993.0,0.271,0.0,4.0
Kevin Gates,Hip Hop,G,Minor,0.5539999999999999,121.918,2016.0,0.358,0.0,4.0
M.I.A.,Hip Hop,C,Major,0.424,119.82,2007.0,0.059,0.00303,4.0
Snoop Dogg,Hip Hop,C#,Major,0.728,204.289,2001.0,0.353,1.15e-05,4.0
Mac Miller,Hip Hop,F#,Minor,0.173,155.158,2018.0,0.517,0.000164,4.0
Chris Brown,Hip Hop,G,Minor,0.339,126.475,2012.0,0.13,0.0,4.0
Kreayshawn,Hip Hop,A#,Major,0.215,130.065,2019.0,0.0503,0.0183,4.0
Wyclef Jean,Hip Hop,E,Minor,0.662,94.459,2004.0,0.308,0.0,4.0
Ludmilla,Hip Hop,C#,Minor,0.496,132.472,2019.0,0.158,0.0,4.0
Slum Village,Hip Hop,G,Major,0.759,94.448,2010.0,0.513,1.59e-05,4.0
Slum Village,Hip Hop,C,Major,0.7929999999999999,94.536,2010.0,0.181,0.789,4.0
Wale,Hip Hop,D,Major,0.487,74.328,2018.0,0.664,0.0,4.0
Ashanti,Hip Hop,C#,Minor,0.623,117.676,2014.0,0.055,0.0,4.0
Gucci Mane,Hip Hop,D,Major,0.438,142.922,2015.0,0.387,0.0,4.0
Gucci Mane,Hip Hop,A,Major,0.502,87.98899999999998,2013.0,0.24,0.0,4.0
Obie Trice,Hip Hop,C#,Major,0.7120000000000001,94.167,2009.0,0.282,0.0,4.0
Chris Brown,Hip Hop,D,Major,0.17800000000000002,183.068,2012.0,0.0656,0.0,3.0
E-40,Hip Hop,C#,Major,0.3670000000000001,110.967,2019.0,0.198,0.0,4.0
Wu-Tang Clan,Hip Hop,F#,Minor,0.4320000000000001,119.988,2014.0,0.236,6.63e-05,4.0
Wiz Khalifa,Hip Hop,F,Minor,0.5710000000000001,145.032,2018.0,0.0716,0.0,4.0
21 Savage,Hip Hop,G#,Major,0.0703,80.01100000000002,2018.0,0.551,2.09e-05,4.0
21 Savage,Hip Hop,C#,Major,0.274,155.029,2017.0,0.259,0.787,4.0
Ludmilla,Hip Hop,A#,Minor,0.36,132.015,2019.0,0.129,3.2299999999999986e-05,4.0
Wyclef Jean,Hip Hop,D,Minor,0.359,90.31,2002.0,0.277,0.0,4.0
Wu-Tang Clan,Hip Hop,D#,Minor,0.461,95.037,2014.0,0.213,0.0,4.0
Dustin,Hip Hop,C,Major,0.28,133.161,2005.0,0.0302,0.000155,4.0
Mary J. Blige,Hip Hop,D#,Minor,0.603,141.84799999999996,1997.0,0.0412,2.84e-06,4.0
Kris Kross,Hip Hop,B,Major,0.424,92.118,1993.0,0.338,0.00149,4.0
"Luiz, o Visitante",Hip Hop,A,Major,0.7020000000000001,135.952,2019.0,0.289,0.0,4.0
Common,Hip Hop,G,Major,0.525,84.86399999999998,1992.0,0.316,0.00011,4.0
Kris Kross,Hip Hop,B,Minor,0.889,161.92700000000005,1992.0,0.168,0.0913,4.0
Ludmilla,Hip Hop,B,Major,0.556,133.039,2020.0,0.0333,0.0,4.0
Black Eyed Peas,Hip Hop,C#,Major,0.606,117.033,2020.0,0.102,4.16e-05,4.0
Ludmilla,Hip Hop,C#,Minor,0.547,133.019,2019.0,0.138,0.0,4.0
M.I.A.,Hip Hop,B,Minor,0.611,96.839,2001.0,0.0494,1.23e-06,4.0
Black Moon,Hip Hop,G,Major,0.8,96.093,1996.0,0.298,0.0,4.0
Will Smith,Hip Hop,B,Major,0.868,105.316,2002.0,0.0837,0.000199,4.0
Flo Rida,Hip Hop,B,Minor,0.402,80.975,2008.0,0.0758,0.0,4.0
Ciara,Hip Hop,C#,Major,0.5920000000000001,127.889,2006.0,0.102,0.00146,4.0
Kevin Gates,Hip Hop,A,Major,0.528,134.966,2018.0,0.313,0.0,4.0
Kehlani,Hip Hop,G#,Major,0.324,172.007,2017.0,0.054000000000000006,0.00128,4.0
Travie McCoy,Hip Hop,F,Minor,0.889,145.053,2010.0,0.0786,0.0,4.0
Wu-Tang Clan,Hip Hop,B,Major,0.446,92.409,1992.0,0.077,0.826,4.0
Wu-Tang Clan,Hip Hop,A#,Minor,0.445,92.582,1992.0,0.334,0.01,4.0
Mystikal,Hip Hop,C#,Minor,0.252,139.964,2000.0,0.11,0.0,4.0
Kevin Gates,Hip Hop,F#,Major,0.384,80.775,2016.0,0.311,0.0,5.0
Travie McCoy,Hip Hop,C#,Major,0.512,79.235,2010.0,0.142,1.56e-06,4.0
Ciara,Hip Hop,D,Major,0.6779999999999999,123.995,2015.0,0.112,0.000326,4.0
Ray J,Hip Hop,C,Major,0.6509999999999999,132.013,2008.0,0.11,0.0,4.0
M.I.A.,Hip Hop,A,Major,0.59,95.425,2001.0,0.0689,0.0,4.0
Flo Rida,Hip Hop,C,Major,0.26,106.044,2008.0,0.102,0.0,4.0
Chris Brown,Hip Hop,D#,Major,0.563,111.962,2005.0,0.0273,0.0,4.0
Common,Hip Hop,G,Major,0.488,90.808,1997.0,0.382,0.000113,4.0
Chris Brown,Hip Hop,B,Minor,0.105,133.84799999999998,2019.0,0.0336,0.0,3.0
M.I.A.,Hip Hop,C,Major,0.464,186.909,2001.0,0.13699999999999998,0.0,4.0
Soulja Boy,Hip Hop,F,Major,0.269,105.986,2018.0,0.08199999999999999,0.0,4.0
Meek Mill,Hip Hop,G#,Major,0.46,164.213,2018.0,0.251,0.0,4.0
Souleye,Hip Hop,D,Minor,0.0379,119.981,2011.0,0.0474,0.736,4.0
Kris Kross,Hip Hop,A#,Minor,0.547,97.305,1993.0,0.19,4.26e-05,4.0
Mystikal,Hip Hop,D,Minor,0.7340000000000001,92.394,2001.0,0.276,1.3e-06,4.0
Kris Kross,Hip Hop,A#,Minor,0.568,97.299,1993.0,0.222,7.13e-05,4.0
Ludmilla,Hip Hop,E,Minor,0.841,142.113,2020.0,0.0318,0.0,4.0
Chris Brown,Hip Hop,F,Major,0.517,99.688,2014.0,0.0265,0.0,4.0
Ciara,Hip Hop,F#,Major,0.4370000000000001,122.219,2004.0,0.0653,0.0,4.0
Mac Miller,Hip Hop,B,Major,0.222,139.786,2012.0,0.206,1.89e-06,4.0
Tinashe,Hip Hop,C#,Major,0.29600000000000004,111.007,2020.0,0.0511,0.000742,4.0
M.I.A.,Hip Hop,A,Major,0.376,121.549,2001.0,0.121,1.18e-06,4.0
Chris Brown,Hip Hop,G,Major,0.441,125.993,2005.0,0.0335,0.00546,4.0
Common,Hip Hop,A#,Major,0.35600000000000004,116.802,1994.0,0.911,0.32299999999999995,4.0
Wyclef Jean,Hip Hop,B,Minor,0.453,90.153,1997.0,0.28600000000000003,3.13e-06,4.0
Chris Brown,Hip Hop,G,Major,0.5710000000000001,150.976,2005.0,0.0366,0.000556,4.0
Kevin Gates,Hip Hop,C,Major,0.473,76.493,2016.0,0.398,0.0,5.0
Gym Class Heroes,Hip Hop,A#,Major,0.649,129.989,2012.0,0.0397,7.54e-06,4.0
Gym Class Heroes,Hip Hop,A#,Major,0.591,129.998,2012.0,0.0324,0.303,4.0
T.I.,Hip Hop,G,Major,0.581,91.805,2001.0,0.3,0.0,4.0
Calle 13,Hip Hop,A,Major,0.883,87.991,2005.0,0.101,0.0,4.0
Soulja Boy,Hip Hop,A#,Minor,0.262,139.955,2020.0,0.395,0.0,4.0
Wiz Khalifa,Hip Hop,C#,Major,0.281,74.993,2018.0,0.224,0.0,4.0
Bow Wow,Hip Hop,F#,Major,0.428,92.007,2005.0,0.21600000000000005,0.0,4.0
Omarion,Hip Hop,C#,Major,0.35100000000000003,97.993,2020.0,0.041,0.0105,4.0
Wale,Hip Hop,F#,Minor,0.439,113.021,2019.0,0.165,1.28e-05,4.0
Chris Brown,Hip Hop,A,Major,0.239,76.247,2019.0,0.0667,0.0,4.0
Wyclef Jean,Hip Hop,F,Major,0.332,93.111,2003.0,0.0554,0.0,3.0
21 Savage,Hip Hop,A,Major,0.157,163.02100000000004,2017.0,0.391,0.119,4.0
Xzibit,Hip Hop,B,Minor,0.175,84.619,2004.0,0.311,0.0,4.0
50 Cent,Hip Hop,F#,Minor,0.698,93.933,2003.0,0.263,0.0,4.0
Chris Brown,Hip Hop,F,Minor,0.511,122.926,2019.0,0.0611,0.0,4.0
21 Savage,Hip Hop,F#,Minor,0.387,158.05,2017.0,0.373,1.55e-05,4.0
Usher,Hip Hop,F,Major,0.636,152.279,2020.0,0.101,0.0,4.0
Kehlani,Hip Hop,A#,Major,0.0493,132.203,2020.0,0.0441,0.0,4.0
Twista,Hip Hop,B,Major,0.588,143.97899999999996,2004.0,0.117,3.9299999999999986e-05,4.0
Kevin Gates,Hip Hop,F,Minor,0.635,159.861,2019.0,0.27,0.0,4.0
