Output_Data/hiphop_word_count.csv
words,0
.,380461
",",198560
i,124220
the,121983
you,112990
to,69109
a,68394
and,68216
it,56138
me,55550
my,49806
in,42164
i'm,39488
that,38126
on,35694
like,30838
your,28256
up,25410
of,25092
we,24598
with,24041
get,22995
?,22460
for,22276
know,22076
be,21705
got,21678
all,21374
don't,21267
is,21231
this,20026
so,19948
but,19714
what,18584
just,17981
they,16118
do,16110
no,15732
when,15282
it's,14945
!,14944
can,14015
out,13899
now,13853
ain't,13645
if,13615
go,12892
love,12540
she,12406
yeah,11863
baby,11480
see,10948
oh,10397
back,10338
one,10266
down,10232
was,10193
nigga,9968
make,9946
at,9831
shit,9583
girl,9358
say,9117
want,9071
let,9000
her,8980
wanna,8950
ya,8865
from,8851
how,8263
time,8123
never,8100
can't,8092
not,7784
man,7738
right,7680
come,7671
take,7646
cause,7490
fuck,7479
chorus,7179
that's,7163
he,7139
way,6742
them,6686
off,6599
tell,6579
bitch,6290
need,6275
you're,6270
about,6251
here,6240
some,6218
then,6202
have,6106
as,6048
keep,5955
niggas,5650
gotta,5633
been,5619
or,5416
money,5388
life,5326
put,5319
give,5272
who,5246
more,5243
feel,5205
think,5188
i'll,5091
these,4886
where,4813
are,4809
why,4756
gonna,4728
too,4547
uh,4533
still,4517
could,4506
said,4503
'em,4432
yo,4429
good,4390
look,4358
over,4339
us,4312
there,4249
ass,4151
even,4096
had,4067
through,3972
hey,3936
only,3861
'cause,3845
better,3773
call,3718
real,3712
hit,3703
will,3702
by,3699
around,3691
t,3649
night,3611
him,3522
verse,3506
show,3468
his,3453
stop,3388
than,3357
day,3353
really,3309
every,3259
boy,3244
little,3206
world,3191
y'all,3155
would,3046
game,2991
ever,2935
an,2893
hard,2878
mind,2870
turn,2861
big,2850
new,2827
let's,2760
thing,2738
won't,2728
did,2701
la,2696
em,2682
leave,2581
two,2576
its,2564
play,2530
work,2521
away,2511
wit,2504
bad,2502
made,2501
gon',2499
s,2491
i've,2466
niggaz,2465
gone,2453
again,2448
before,2440
long,2431
done,2428
name,2415
live,2415
talk,2384
much,2381
head,2380
stay,2380
run,2370
hold,2363
da,2355
heart,2354
home,2342
try,2294
high,2291
tonight,2287
always,2281
am,2279
everything,2261
things,2260
going,2257
ooh,2239
body,2237
2,2232
u,2228
ride,2226
same,2211
something,2198
hear,2180
while,2171
damn,2144
our,2139
crazy,2136
bitches,2135
face,2121
nothing,2116
people,2113
watch,2109
told,2091
m,2061
what's,2047
well,2015
there's,2006
god,1983
girls,1959
find,1957
into,1950
should,1922
another,1920
first,1903
i'ma,1901
bring,1896
ready,1879
huh,1877
move,1874
cuz,1871
might,1867
im,1865
everybody,1863
hot,1857
whole,1848
rock,1841
top,1834
eyes,1832
we're,1815
best,1803
bout,1803
1,1785
hook,1784
black,1776
drop,1773
mean,1772
hands,1764
last,1758
club,1757
break,1752
beat,1739
nobody,1738
came,1726
thought,1691
other,1671
young,1670
ha,1644
o,1642
she's,1635
hate,1618
g,1606
change,1602
party,1598
rap,1595
believe,1595
roll,1589
walk,1586
left,1586
please,1569
seen,1567
wrong,1567
used,1565
own,1559
hoes,1544
tryna,1541
die,1526
mine,1521
throw,1511
pop,1509
getting,1500
feeling,1493
without,1483
trying,1479
side,1478
e,1462
enough,1460
dick,1460
city,1430
start,1427
na,1419
pain,1419
check,1418
many,1418
d,1409
fly,1408
lot,1401
ask,1398
house,1397
yea,1389
dance,1386
pull,1380
till,1378
ah,1376
talking,1375
light,1359
you'll,1354
fucking,1354
were,1353
heard,1351
wait,1347
fall,1339
aint,1330
though,1329
because,1328
pussy,1325
looking,1325
hood,1321
shake,1319
streets,1318
didn't,1314
b,1312
white,1302
next,1299
friends,1299
slow,1283
he's,1283
n,1275
straight,1264
ay,1263
kill,1259
coming,1257
touch,1257
end,1254
'bout,1248
after,1248
myself,1239
hand,1239
fuckin,1237
hope,1231
alone,1210
floor,1207
fuckin',1203
hell,1200
shawty,1200
somebody,1200
low,1196
blow,1195
guess,1195
i'd,1193
car,1181
place,1181
song,1180
care,1169
jay,1167
doing,1166
old,1165
maybe,1163
block,1155
boys,1149
dont,1144
three,1144
mad,1136
listen,1132
3,1131
stand,1128
cold,1124
front,1119
catch,1118
inside,1118
music,1117
mama,1116
until,1106
took,1105
round,1104
don,1104
since,1102
flow,1100
kiss,1095
matter,1091
smoke,1084
knew,1083
their,1080
shot,1074
act,1073
fight,1070
z,1047
remember,1045
times,1039
help,1036
went,1031
full,1029
lights,1028
open,1016
together,1016
days,1006
must,1005
fire,1000
cut,997
free,997
lost,996
understand,995
tryin,991
wish,990
any,990
bet,990
whatever,989
gon,987
line,987
eminem,985
town,983
cash,980
jump,979
hurt,968
pay,962
those,961
i'mma,958
king,957
sure,954
alright,948
else,947
true,947
p,945
lose,943
miss,941
phone,941
far,936
set,934
cool,934
yes,933
dirty,933
door,931
already,926
mouth,922
lil,916
forget,911
close,907
whoa,900
lay,898
gun,895
probably,895
started,895
anything,893
drink,893
sound,890
under,890
late,883
forever,881
ladies,878
couldn't,873
deep,872
bounce,871
fast,869
gave,868
found,865
l,863
sick,863
goes,862
dead,862
step,851
outta,849
saying,846
making,843
buy,837
you've,836
gettin',835
street,833
half,832
lie,831
daddy,831
word,829
paper,828
goin',824
ice,824
uhh,820
;,819
someone,817
words,816
broke,814
caught,814
air,813
friend,812
40,810
spit,810
yourself,810
repeat,808
babe,807
f,806
sit,804
once,804
wasn't,802
trust,802
nothin',800
dream,799
kids,798
thats,797
sexy,797
cry,797
shorty,795
x2,795
2x,795
truth,795
couple,794
has,793
crack,793
'til,792
room,792
sky,790
thinking,789
hoe,788
bust,785
tha,784
sometimes,784
four,782
comes,781
fucked,781
dope,776
behind,769
red,768
r,767
minute,767
gettin,766
five,766
living,765
c,765
fat,762
control,761
soul,760
kick,758
ball,758
shoot,758
swear,757
being,749
pass,747
pimp,746
talkin',746
running,746
wanted,744
ho,741
nice,737
dog,737
pick,737
different,734
pretty,730
both,727
bang,727
type,723
lady,723
motherfucker,722
meet,720
use,719
homie,718
yo',718
most,718
rich,718
hop,715
gold,714
number,712
lookin,710
eat,709
thang,707
quick,707
stick,706
makes,706
sleep,705
morning,703
tried,699
spend,697
rest,697
okay,697
women,694
chick,693
style,693
sing,693
bed,687
school,687
rain,687
hundred,686
six,686
wouldn't,686
waiting,686
reason,685
nah,683
lookin',683
4,682
shine,680
kid,679
million,678
goin,675
sweet,672
x,671
smile,670
lil',670
soon,667
who's,664
easy,657
talkin,656
blood,655
star,654
fine,654
tryin',650
haters,650
momma,649
mic,647
today,647
dat,646
tired,645
sex,644
we'll,644
spot,643
gets,641
k,641
ghetto,641
scared,636
lets,634
ohh,634
feels,634
years,634
drive,633
boom,632
deal,630
past,629
part,628
saw,626
knows,625
bridge,624
wake,624
murder,623
year,620
feet,618
sun,617
chance,615
follow,615
family,612
doin,611
tight,610
clothes,610
dreams,610
fool,609
water,608
plus,607
50,606
doin',605
neck,602
middle,600
grab,600
shady,599
mother,598
hair,598
booty,597
son,597
til,596
promise,596
c'mon,595
bag,595
j,594
fresh,590
business,589
mr,589
ground,589
sorry,588
hustle,588
taking,586
dark,584
bump,584
cant,583
grind,582
push,576
brain,575
picture,575
speak,575
comin,575
ma,574
lord,574
stuck,573
strong,572
war,572
chain,571
south,571
death,570
heat,570
paid,568
save,568
yours,565
rappers,564
kind,562
bit,562
ya'll,561
weed,561
blue,558
cars,557
comin',553
5,552
freak,552
kinda,550
holla,549
dj,549
ones,549
gangsta,548
eye,547
worth,547
knock,545
fun,543
shots,540
loose,539
double,539
wit',538
thank,538
does,538
fake,536
alive,536
boss,535
crew,534
born,534
met,533
dough,531
somethin,530
burn,530
respect,530
track,529
send,529
guy,529
second,529
may,529
wonder,529
feelin',527
shoes,527
gimme,527
each,524
none,522
re,522
woman,521
fact,519
rhyme,518
aye,513
perfect,510
happy,509
crib,507
wild,502
somethin',501
buck,501
learn,498
bottle,498
ring,498
happen,497
fame,497
write,496
breathe,496
boo,495
green,494
dollar,494
flip,493
point,490
wall,489
imma,488
playing,487
peace,486
win,486
everyday,486
hello,483
rather,482
lips,481
road,478
intro,477
count,476
joe,475
supposed,474
nine,474
team,474
known,474
ten,473
beautiful,470
taste,469
seem,469
between,468
hip,467
piece,467
ill,466
called,465
click,464
bought,464
they're,464
nothin,461
handle,461
sayin',460
yet,459
whip,459
chest,459
thug,459
nelly,456
treat,456
ahead,455
